Workbook

Sheet Executive Summary
A1: Unified Commerce — Executive Summary
A2: Source: dbt_dev_marts.mart_monthly_kpis and spark_revenue_trends, unified_commerce_pipeline (Postgres + dbt + Airflow + PySpark)
A4: Total Revenue | B4: Total Orders | C4: Overall Margin % | D4: Avg Order Value
A5: =SUM('Monthly KPIs (raw)'!$F$2:$F$1501) -> 36739916 | B5: =SUM('Monthly KPIs (raw)'!$D$2:$D$1501) -> 59248 | C5: =SUM('Monthly KPIs (raw)'!$G$2:$G$1501)/SUM('Monthly KPIs (raw)'!$F$2:$F$1501) -> 0.66413946 | D5: =SUM('Monthly KPIs (raw)'!$F$2:$F$1501)/SUM('Monthly KPIs (raw)'!$D$2:$D$1501) -> 620.1039
A8: Revenue by Region
A9: Region | B9: Revenue | C9: Margin | D9: Margin %
A10: Midwest | B10: =SUMIF('Monthly KPIs (raw)'!$B$2:$B$1501,A10,'Monthly KPIs (raw)'!$F$2:$F$1501) -> 7342358.4 | C10: =SUMIF('Monthly KPIs (raw)'!$B$2:$B$1501,A10,'Monthly KPIs (raw)'!$G$2:$G$1501) -> 4910923.7 | D10: =C10/B10 -> 0.66884827
A11: Northeast | B11: =SUMIF('Monthly KPIs (raw)'!$B$2:$B$1501,A11,'Monthly KPIs (raw)'!$F$2:$F$1501) -> 6848525.5 | C11: =SUMIF('Monthly KPIs (raw)'!$B$2:$B$1501,A11,'Monthly KPIs (raw)'!$G$2:$G$1501) -> 4503566.3 | D11: =C11/B11 -> 0.65759648
A12: Southeast | B12: =SUMIF('Monthly KPIs (raw)'!$B$2:$B$1501,A12,'Monthly KPIs (raw)'!$F$2:$F$1501) -> 7069434.5 | C12: =SUMIF('Monthly KPIs (raw)'!$B$2:$B$1501,A12,'Monthly KPIs (raw)'!$G$2:$G$1501) -> 4718752.7 | D12: =C12/B12 -> 0.66748659
A13: Southwest | B13: =SUMIF('Monthly KPIs (raw)'!$B$2:$B$1501,A13,'Monthly KPIs (raw)'!$F$2:$F$1501) -> 8154638.8 | C13: =SUMIF('Monthly KPIs (raw)'!$B$2:$B$1501,A13,'Monthly KPIs (raw)'!$G$2:$G$1501) -> 5433313.6 | D13: =C13/B13 -> 0.66628501
A14: West | B14: =SUMIF('Monthly KPIs (raw)'!$B$2:$B$1501,A14,'Monthly KPIs (raw)'!$F$2:$F$1501) -> 7324958.8 | C14: =SUMIF('Monthly KPIs (raw)'!$B$2:$B$1501,A14,'Monthly KPIs (raw)'!$G$2:$G$1501) -> 4833871.6 | D14: =C14/B14 -> 0.65991792
A17: Revenue by Category
A18: Category | B18: Revenue | C18: Margin | D18: Margin %
A19: Apparel | B19: =SUMIF('Monthly KPIs (raw)'!$C$2:$C$1501,A19,'Monthly KPIs (raw)'!$F$2:$F$1501) -> 3401267 | C19: =SUMIF('Monthly KPIs (raw)'!$C$2:$C$1501,A19,'Monthly KPIs (raw)'!$G$2:$G$1501) -> 2204536.7 | D19: =C19/B19 -> 0.6481516
A20: Beauty | B20: =SUMIF('Monthly KPIs (raw)'!$C$2:$C$1501,A20,'Monthly KPIs (raw)'!$F$2:$F$1501) -> 4289444.7 | C20: =SUMIF('Monthly KPIs (raw)'!$C$2:$C$1501,A20,'Monthly KPIs (raw)'!$G$2:$G$1501) -> 3131949.8 | D20: =C20/B20 -> 0.73015274
A21: Books | B21: =SUMIF('Monthly KPIs (raw)'!$C$2:$C$1501,A21,'Monthly KPIs (raw)'!$F$2:$F$1501) -> 5147576.2 | C21: =SUMIF('Monthly KPIs (raw)'!$C$2:$C$1501,A21,'Monthly KPIs (raw)'!$G$2:$G$1501) -> 2931301.1 | D21: =C21/B21 -> 0.56945268
A22: Electronics | B22: =SUMIF('Monthly KPIs (raw)'!$C$2:$C$1501,A22,'Monthly KPIs (raw)'!$F$2:$F$1501) -> 3149985.2 | C22: =SUMIF('Monthly KPIs (raw)'!$C$2:$C$1501,A22,'Monthly KPIs (raw)'!$G$2:$G$1501) -> 2027144.6 | D22: =C22/B22 -> 0.643541
A23: Grocery | B23: =SUMIF('Monthly KPIs (raw)'!$C$2:$C$1501,A23,'Monthly KPIs (raw)'!$F$2:$F$1501) -> 2751739.2 | C23: =SUMIF('Monthly KPIs (raw)'!$C$2:$C$1501,A23,'Monthly KPIs (raw)'!$G$2:$G$1501) -> 1601764.5 | D23: =C23/B23 -> 0.58209169
A24: Home & Kitchen | B24: =SUMIF('Monthly KPIs (raw)'!$C$2:$C$1501,A24,'Monthly KPIs (raw)'!$F$2:$F$1501) -> 3697804.2 | C24: =SUMIF('Monthly KPIs (raw)'!$C$2:$C$1501,A24,'Monthly KPIs (raw)'!$G$2:$G$1501) -> 2477222 | D24: =C24/B24 -> 0.66991701
A25: Office Supplies | B25: =SUMIF('Monthly KPIs (raw)'!$C$2:$C$1501,A25,'Monthly KPIs (raw)'!$F$2:$F$1501) -> 2712063.4 | C25: =SUMIF('Monthly KPIs (raw)'!$C$2:$C$1501,A25,'Monthly KPIs (raw)'!$G$2:$G$1501) -> 1765450.4 | D25: =C25/B25 -> 0.65096205
A26: Pet Supplies | B26: =SUMIF('Monthly KPIs (raw)'!$C$2:$C$1501,A26,'Monthly KPIs (raw)'!$F$2:$F$1501) -> 5183874.7 | C26: =SUMIF('Monthly KPIs (raw)'!$C$2:$C$1501,A26,'Monthly KPIs (raw)'!$G$2:$G$1501) -> 3691802.9 | D26: =C26/B26 -> 0.71217056
A27: Sports & Outdoors | B27: =SUMIF('Monthly KPIs (raw)'!$C$2:$C$1501,A27,'Monthly KPIs (raw)'!$F$2:$F$1501) -> 2958848.4 | C27: =SUMIF('Monthly KPIs (raw)'!$C$2:$C$1501,A27,'Monthly KPIs (raw)'!$G$2:$G$1501) -> 2497822.7 | D27: =C27/B27 -> 0.84418746
A28: Toys | B28: =SUMIF('Monthly KPIs (raw)'!$C$2:$C$1501,A28,'Monthly KPIs (raw)'!$F$2:$F$1501) -> 3447312.8 | C28: =SUMIF('Monthly KPIs (raw)'!$C$2:$C$1501,A28,'Monthly KPIs (raw)'!$G$2:$G$1501) -> 2071433.1 | D28: =C28/B28 -> 0.60088341
A31: Highlights
A32: Top region by revenue | B32: =INDEX($A$10:$A$14,MATCH(MAX($B$10:$B$14),$B$10:$B$14,0)) -> Southwest
A33: Top category by revenue | B33: =INDEX($A$19:$A$28,MATCH(MAX($B$19:$B$28),$B$19:$B$28,0)) -> Pet Supplies
A34: Lowest-margin category | B34: =INDEX($A$19:$A$28,MATCH(MIN($D$19:$D$28),$D$19:$D$28,0)) -> Books
A37: Monthly Revenue Trend
A38: Month | B38: Revenue | C38: Orders
A39: 2024-01-01 | B39: =SUMIF('Monthly KPIs (raw)'!$A$2:$A$1501,A39,'Monthly KPIs (raw)'!$F$2:$F$1501) -> 1222388.5 | C39: =SUMIF('Monthly KPIs (raw)'!$A$2:$A$1501,A39,'Monthly KPIs (raw)'!$D$2:$D$1501) -> 1985
A40: 2024-02-01 | B40: =SUMIF('Monthly KPIs (raw)'!$A$2:$A$1501,A40,'Monthly KPIs (raw)'!$F$2:$F$1501) -> 1145680 | C40: =SUMIF('Monthly KPIs (raw)'!$A$2:$A$1501,A40,'Monthly KPIs (raw)'!$D$2:$D$1501) -> 1854
A41: 2024-03-01 | B41: =SUMIF('Monthly KPIs (raw)'!$A$2:$A$1501,A41,'Monthly KPIs (raw)'!$F$2:$F$1501) -> 1275453.6 | C41: =SUMIF('Monthly KPIs (raw)'!$A$2:$A$1501,A41,'Monthly KPIs (raw)'!$D$2:$D$1501) -> 2076
A42: 2024-04-01 | B42: =SUMIF('Monthly KPIs (raw)'!$A$2:$A$1501,A42,'Monthly KPIs (raw)'!$F$2:$F$1501) -> 1161318.3 | C42: =SUMIF('Monthly KPIs (raw)'!$A$2:$A$1501,A42,'Monthly KPIs (raw)'!$D$2:$D$1501) -> 1886
A43: 2024-05-01 | B43: =SUMIF('Monthly KPIs (raw)'!$A$2:$A$1501,A43,'Monthly KPIs (raw)'!$F$2:$F$1501) -> 1267106.4 | C43: =SUMIF('Monthly KPIs (raw)'!$A$2:$A$1501,A43,'Monthly KPIs (raw)'!$D$2:$D$1501) -> 2036
A44: 2024-06-01 | B44: =SUMIF('Monthly KPIs (raw)'!$A$2:$A$1501,A44,'Monthly KPIs (raw)'!$F$2:$F$1501) -> 1178827.2 | C44: =SUMIF('Monthly KPIs (raw)'!$A$2:$A$1501,A44,'Monthly KPIs (raw)'!$D$2:$D$1501) -> 1881
A45: 2024-07-01 | B45: =SUMIF('Monthly KPIs (raw)'!$A$2:$A$1501,A45,'Monthly KPIs (raw)'!$F$2:$F$1501) -> 1254220.1 | C45: =SUMIF('Monthly KPIs (raw)'!$A$2:$A$1501,A45,'Monthly KPIs (raw)'!$D$2:$D$1501) -> 1998
A46: 2024-08-01 | B46: =SUMIF('Monthly KPIs (raw)'!$A$2:$A$1501,A46,'Monthly KPIs (raw)'!$F$2:$F$1501) -> 1221883.5 | C46: =SUMIF('Monthly KPIs (raw)'!$A$2:$A$1501,A46,'Monthly KPIs (raw)'!$D$2:$D$1501) -> 1947
A47: 2024-09-01 | B47: =SUMIF('Monthly KPIs (raw)'!$A$2:$A$1501,A47,'Monthly KPIs (raw)'!$F$2:$F$1501) -> 1192488.3 | C47: =SUMIF('Monthly KPIs (raw)'!$A$2:$A$1501,A47,'Monthly KPIs (raw)'!$D$2:$D$1501) -> 1923
A48: 2024-10-01 | B48: =SUMIF('Monthly KPIs (raw)'!$A$2:$A$1501,A48,'Monthly KPIs (raw)'!$F$2:$F$1501) -> 1262696.5 | C48: =SUMIF('Monthly KPIs (raw)'!$A$2:$A$1501,A48,'Monthly KPIs (raw)'!$D$2:$D$1501) -> 2022
A49: 2024-11-01 | B49: =SUMIF('Monthly KPIs (raw)'!$A$2:$A$1501,A49,'Monthly KPIs (raw)'!$F$2:$F$1501) -> 1129160 | C49: =SUMIF('Monthly KPIs (raw)'!$A$2:$A$1501,A49,'Monthly KPIs (raw)'!$D$2:$D$1501) -> 1846
...

Sheet Monthly KPIs (raw)
A1: order_month | B1: region | C1: category | D1: order_count | E1: units_sold | F1: total_revenue | G1: total_gross_margin | H1: margin_pct
A2: 2024-01-01 | B2: Midwest | C2: Apparel | D2: 46 | E2: 136 | F2: 28897.51 | G2: 18354.88 | H2: 63.52
A3: 2024-01-01 | B3: Midwest | C3: Beauty | D3: 41 | E3: 113 | F3: 24810.48 | G3: 17337.35 | H3: 69.88
A4: 2024-01-01 | B4: Midwest | C4: Books | D4: 60 | E4: 179 | F4: 38569.24 | G4: 24881.99 | H4: 64.51
A5: 2024-01-01 | B5: Midwest | C5: Electronics | D5: 29 | E5: 79 | F5: 14016.73 | G5: 8469.43 | H5: 60.42
A6: 2024-01-01 | B6: Midwest | C6: Grocery | D6: 34 | E6: 104 | F6: 16948.8 | G6: 8915.23 | H6: 52.6
A7: 2024-01-01 | B7: Midwest | C7: Home & Kitchen | D7: 45 | E7: 135 | F7: 21495.59 | G7: 13777.04 | H7: 64.09
A8: 2024-01-01 | B8: Midwest | C8: Office Supplies | D8: 34 | E8: 118 | F8: 20708.18 | G8: 11970.83 | H8: 57.81
A9: 2024-01-01 | B9: Midwest | C9: Pet Supplies | D9: 48 | E9: 162 | F9: 44399.82 | G9: 32896.13 | H9: 74.09
A10: 2024-01-01 | B10: Midwest | C10: Sports & Outdoors | D10: 29 | E10: 76 | F10: 19236.43 | G10: 16360.1 | H10: 85.05
A11: 2024-01-01 | B11: Midwest | C11: Toys | D11: 46 | E11: 130 | F11: 22521.93 | G11: 13763.5 | H11: 61.11
A12: 2024-01-01 | B12: Northeast | C12: Apparel | D12: 37 | E12: 101 | F12: 15457.94 | G12: 8174.87 | H12: 52.88
A13: 2024-01-01 | B13: Northeast | C13: Beauty | D13: 28 | E13: 89 | F13: 19485.43 | G13: 14316.19 | H13: 73.47
... A1501: 2026-06-01 | B1501: West | C1501: Toys | D1501: 40 | E1501: 112 | F1501: 17534.4 | G1501: 9440.42 | H1501: 53.84

Sheet Daily Revenue Trend (raw)
A1: order_date | B1: daily_revenue | C1: daily_order_count | D1: revenue_rolling_7d | E1: revenue_rolling_30d | F1: avg_daily_revenue_7d | G1: avg_daily_revenue_30d
A2: 2024-01-01 | B2: 37936.65 | C2: 65 | D2: 37936.65 | E2: 37936.65 | F2: 37936.65 | G2: 37936.65
A3: 2024-01-02 | B3: 36538.48 | C3: 61 | D3: 74475.13 | E3: 74475.13 | F3: 37237.57 | G3: 37237.57
A4: 2024-01-03 | B4: 39064.22 | C4: 68 | D4: 113539.35 | E4: 113539.35 | F4: 37846.45 | G4: 37846.45
A5: 2024-01-04 | B5: 47143.46 | C5: 78 | D5: 160682.81 | E5: 160682.81 | F5: 40170.7 | G5: 40170.7
A6: 2024-01-05 | B6: 43377.65 | C6: 68 | D6: 204060.46 | E6: 204060.46 | F6: 40812.09 | G6: 40812.09
A7: 2024-01-06 | B7: 36096.33 | C7: 63 | D7: 240156.79 | E7: 240156.79 | F7: 40026.13 | G7: 40026.13
A8: 2024-01-07 | B8: 46222.28 | C8: 66 | D8: 286379.07 | E8: 286379.07 | F8: 40911.3 | G8: 40911.3
A9: 2024-01-08 | B9: 35461.62 | C9: 57 | D9: 283904.04 | E9: 321840.69 | F9: 40557.72 | G9: 40230.09
A10: 2024-01-09 | B10: 33875.41 | C10: 59 | D10: 281240.97 | E10: 355716.1 | F10: 40177.28 | G10: 39524.01
A11: 2024-01-10 | B11: 45484.38 | C11: 64 | D11: 287661.13 | E11: 401200.48 | F11: 41094.45 | G11: 40120.05
A12: 2024-01-11 | B12: 46841.94 | C12: 69 | D12: 287359.61 | E12: 448042.42 | F12: 41051.37 | G12: 40731.13
A13: 2024-01-12 | B13: 34439.19 | C13: 59 | D13: 278421.15 | E13: 482481.61 | F13: 39774.45 | G13: 40206.8
... A913: 2026-06-30 | B913: 42696.21 | C913: 68 | D913: 264936.68 | E913: 1193601.7 | F913: 37848.1 | G913: 39786.72
